2025-05-09 14:11:10,471 - exception_logger - ERROR - An error occurred
Traceback (most recent call last):
  File "C:\Users\pawar\AppData\Local\Temp\ipykernel_14408\1009441223.py", line 11, in log_exception
    try: 1/0
         ~^~
ZeroDivisionError: division by zero
